<?xml version="0.0" ?>
<robot name="">
	<link name="base_link">
		<inertial>
			<origin rpy="0.00000 -0.00000 0.00000" xyz="0.00000 0.00000 0.00000"/>
			<mass value="4.00000"/>
			<inertia ixx="0.01063" ixy="0" ixz="0" iyy="0.00875" iyz="0" izz="0.01809"/>
		</inertial>
		<visual>
			<origin rpy="0.00000 -0.00000 0.00000" xyz="0.00000 0.00000 0.00000"/>
			<geometry>
				<mesh filename="assets/liwei_ur_description/meshes/ur10/visual/base.dae" scale="1.00000 1.00000 1.00000"/>
			</geometry>
			<material name="mat_-1_0">
				<color rgba="0.23438 0.72656 0.32812 1.00000" />
			</material>
		</visual>
		<collision>
			<origin rpy="0.00000 -0.00000 0.00000" xyz="0.00000 0.00000 0.00000"/>
			<geometry>
				<mesh filename="assets/liwei_ur_description/meshes/ur10/collision/base.stl" scale="1.00000 1.00000 1.00000"/>
			</geometry>
		</collision>
	</link>
	<link name="shoulder_link">
		<inertial>
			<origin rpy="0.00000 -0.00000 0.00000" xyz="0.00000 0.00000 0.00000"/>
			<mass value="7.77800"/>
			<inertia ixx="0.03989" ixy="0" ixz="0" iyy="0.03770" iyz="0" izz="0.03412"/>
		</inertial>
		<visual>
			<origin rpy="0.00000 -0.00000 0.00000" xyz="0.00000 0.00000 0.00000"/>
			<geometry>
				<mesh filename="assets/liwei_ur_description/meshes/ur10/visual/shoulder.dae" scale="1.00000 1.00000 1.00000"/>
			</geometry>
			<material name="mat_0_0">
				<color rgba="0.23438 0.72656 0.32812 1.00000" />
			</material>
		</visual>
		<collision>
			<origin rpy="0.00000 -0.00000 0.00000" xyz="0.00000 0.00000 0.00000"/>
			<geometry>
				<mesh filename="assets/liwei_ur_description/meshes/ur10/collision/shoulder.stl" scale="1.00000 1.00000 1.00000"/>
			</geometry>
		</collision>
	</link>
	<link name="upper_arm_link">
		<inertial>
			<origin rpy="0.00000 -0.00000 0.00000" xyz="0.00000 0.00000 0.30600"/>
			<mass value="12.93000"/>
			<inertia ixx="0.65013" ixy="0" ixz="0" iyy="0.64040" iyz="0" izz="0.06264"/>
		</inertial>
		<visual>
			<origin rpy="0.00000 -0.00000 0.00000" xyz="0.00000 0.00000 0.00000"/>
			<geometry>
				<mesh filename="assets/liwei_ur_description/meshes/ur10/visual/upperarm.dae" scale="1.00000 1.00000 1.00000"/>
			</geometry>
			<material name="mat_1_0">
				<color rgba="0.95312 0.75781 0.05078 1.00000" />
			</material>
		</visual>
		<collision>
			<origin rpy="0.00000 -0.00000 0.00000" xyz="0.00000 0.00000 0.00000"/>
			<geometry>
				<mesh filename="assets/liwei_ur_description/meshes/ur10/collision/upperarm.stl" scale="1.00000 1.00000 1.00000"/>
			</geometry>
		</collision>
	</link>
	<link name="forearm_link">
		<inertial>
			<origin rpy="0.00000 -0.00000 0.00000" xyz="0.00000 0.00000 0.28615"/>
			<mass value="3.87000"/>
			<inertia ixx="0.15749" ixy="0" ixz="0" iyy="0.15609" iyz="0" izz="0.01167"/>
		</inertial>
		<visual>
			<origin rpy="0.00000 -0.00000 0.00000" xyz="0.00000 0.00000 0.00000"/>
			<geometry>
				<mesh filename="assets/liwei_ur_description/meshes/ur10/visual/forearm.dae" scale="1.00000 1.00000 1.00000"/>
			</geometry>
			<material name="mat_2_0">
				<color rgba="0.85547 0.19531 0.21094 1.00000" />
			</material>
		</visual>
		<collision>
			<origin rpy="0.00000 -0.00000 0.00000" xyz="0.00000 0.00000 0.00000"/>
			<geometry>
				<mesh filename="assets/liwei_ur_description/meshes/ur10/collision/forearm.stl" scale="1.00000 1.00000 1.00000"/>
			</geometry>
		</collision>
	</link>
	<link name="wrist_1_link">
		<inertial>
			<origin rpy="0.00000 -0.00000 0.00000" xyz="0.00000 0.00000 0.00000"/>
			<mass value="1.96000"/>
			<inertia ixx="0.00438" ixy="0" ixz="0" iyy="0.00408" iyz="0" izz="0.00338"/>
		</inertial>
		<visual>
			<origin rpy="0.00000 -0.00000 0.00000" xyz="0.00000 0.00000 0.00000"/>
			<geometry>
				<mesh filename="assets/liwei_ur_description/meshes/ur10/visual/wrist1.dae" scale="1.00000 1.00000 1.00000"/>
			</geometry>
			<material name="mat_3_0">
				<color rgba="0.28125 0.51953 0.92578 1.00000" />
			</material>
		</visual>
		<collision>
			<origin rpy="0.00000 -0.00000 0.00000" xyz="0.00000 0.00000 0.00000"/>
			<geometry>
				<mesh filename="assets/liwei_ur_description/meshes/ur10/collision/wrist1.stl" scale="1.00000 1.00000 1.00000"/>
			</geometry>
		</collision>
	</link>
	<link name="wrist_2_link">
		<inertial>
			<origin rpy="0.00000 -0.00000 0.00000" xyz="0.00000 0.00000 0.00000"/>
			<mass value="1.96000"/>
			<inertia ixx="0.00438" ixy="0" ixz="0" iyy="0.00338" iyz="0" izz="0.00409"/>
		</inertial>
		<visual>
			<origin rpy="0.00000 -0.00000 0.00000" xyz="0.00000 0.00000 0.00000"/>
			<geometry>
				<mesh filename="assets/liwei_ur_description/meshes/ur10/visual/wrist2.dae" scale="1.00000 1.00000 1.00000"/>
			</geometry>
			<material name="mat_4_0">
				<color rgba="0.23438 0.72656 0.32812 1.00000" />
			</material>
		</visual>
		<collision>
			<origin rpy="0.00000 -0.00000 0.00000" xyz="0.00000 0.00000 0.00000"/>
			<geometry>
				<mesh filename="assets/liwei_ur_description/meshes/ur10/collision/wrist2.stl" scale="1.00000 1.00000 1.00000"/>
			</geometry>
		</collision>
	</link>
	<link name="wrist_3_link">
		<inertial>
			<origin rpy="0.00000 -0.00000 0.00000" xyz="0.00000 0.00000 0.00000"/>
			<mass value="0.20200"/>
			<inertia ixx="0.00018" ixy="0" ixz="0" iyy="0.00031" iyz="0" izz="0.00018"/>
		</inertial>
		<visual>
			<origin rpy="0.00000 -0.00000 0.00000" xyz="0.00000 0.00000 0.00000"/>
			<geometry>
				<mesh filename="assets/liwei_ur_description/meshes/ur10/visual/wrist3.dae" scale="1.00000 1.00000 1.00000"/>
			</geometry>
			<material name="mat_5_0">
				<color rgba="0.95312 0.75781 0.05078 1.00000" />
			</material>
		</visual>
		<collision>
			<origin rpy="0.00000 -0.00000 0.00000" xyz="0.00000 0.00000 0.00000"/>
			<geometry>
				<mesh filename="assets/liwei_ur_description/meshes/ur10/collision/wrist3.stl" scale="1.00000 1.00000 1.00000"/>
			</geometry>
		</collision>
	</link>
	<link name="ee_link">
		<inertial>
			<origin rpy="0.00000 -0.00000 0.00000" xyz="0.00000 0.00000 0.00000"/>
			<mass value="1.00000"/>
			<inertia ixx="0.00000" ixy="0" ixz="0" iyy="0.00000" iyz="0" izz="0.00000"/>
		</inertial>
	</link>
	<link name="base_link2">
		<inertial>
			<origin rpy="0.00000 -0.00000 0.00000" xyz="-0.00032 -0.00997 0.03712"/>
			<mass value="0.17578"/>
			<inertia ixx="0.00037" ixy="0" ixz="0" iyy="0.00026" iyz="0" izz="0.00043"/>
		</inertial>
		<visual>
			<origin rpy="0.00000 -0.00000 0.00000" xyz="0.00000 0.00000 0.00000"/>
			<geometry>
				<mesh filename="assets/hybrid_griper_v3/meshes/base_link.STL" scale="1.00000 1.00000 1.00000"/>
			</geometry>
			<material name="mat_-1_0">
				<color rgba="0.79216 0.81961 0.93333 1.00000" />
			</material>
		</visual>
		<collision>
			<origin rpy="0.00000 -0.00000 0.00000" xyz="0.00000 0.00000 0.00000"/>
			<geometry>
				<mesh filename="assets/hybrid_griper_v3/meshes/base_link.STL" scale="1.00000 1.00000 1.00000"/>
			</geometry>
		</collision>
	</link>
	<link name="soft_tip_link">
		<inertial>
			<origin rpy="0.00000 -0.00000 0.00000" xyz="0.05131 0.00000 -0.04336"/>
			<mass value="0.02675"/>
			<inertia ixx="0.00002" ixy="0" ixz="0" iyy="0.00005" iyz="0" izz="0.00003"/>
		</inertial>
		<visual>
			<origin rpy="0.00000 -0.00000 0.00000" xyz="0.00000 0.00000 0.00000"/>
			<geometry>
				<mesh filename="assets/hybrid_griper_v3/meshes/soft_tip_link.STL" scale="1.00000 1.00000 1.00000"/>
			</geometry>
			<material name="mat_0_0">
				<color rgba="0.79216 0.81961 0.93333 1.00000" />
			</material>
		</visual>
		<collision>
			<origin rpy="0.00000 -0.00000 0.00000" xyz="0.00000 0.00000 0.00000"/>
			<geometry>
				<mesh filename="assets/hybrid_griper_v3/meshes/soft_tip_link.STL" scale="1.00000 1.00000 1.00000"/>
			</geometry>
		</collision>
	</link>
	<link name="rigid_link">
		<inertial>
			<origin rpy="0.00000 -0.00000 0.00000" xyz="-0.00000 -0.01181 0.00000"/>
			<mass value="0.00082"/>
			<inertia ixx="0.00000" ixy="0" ixz="0" iyy="0.00000" iyz="0" izz="0.00000"/>
		</inertial>
		<visual>
			<origin rpy="0.00000 -0.00000 0.00000" xyz="0.00000 0.00000 0.00000"/>
			<geometry>
				<mesh filename="assets/hybrid_griper_v3/meshes/rigid_link.STL" scale="1.00000 1.00000 1.00000"/>
			</geometry>
			<material name="mat_1_0">
				<color rgba="0.79216 0.81961 0.93333 1.00000" />
			</material>
		</visual>
		<collision>
			<origin rpy="0.00000 -0.00000 0.00000" xyz="0.00000 0.00000 0.00000"/>
			<geometry>
				<mesh filename="assets/hybrid_griper_v3/meshes/rigid_link.STL" scale="1.00000 1.00000 1.00000"/>
			</geometry>
		</collision>
	</link>
	<link name="rigid_tip_link">
		<inertial>
			<origin rpy="0.00000 -0.00000 0.00000" xyz="-0.04601 -0.00007 -0.07829"/>
			<mass value="0.01862"/>
			<inertia ixx="0.00003" ixy="0" ixz="0" iyy="0.00004" iyz="0" izz="0.00001"/>
		</inertial>
		<visual>
			<origin rpy="0.00000 -0.00000 0.00000" xyz="0.00000 0.00000 0.00000"/>
			<geometry>
				<mesh filename="assets/hybrid_griper_v3/meshes/rigid_tip_link.STL" scale="1.00000 1.00000 1.00000"/>
			</geometry>
			<material name="mat_2_0">
				<color rgba="0.79216 0.81961 0.93333 1.00000" />
			</material>
		</visual>
		<collision>
			<origin rpy="0.00000 -0.00000 0.00000" xyz="0.00000 0.00000 0.00000"/>
			<geometry>
				<mesh filename="assets/hybrid_griper_v3/meshes/rigid_tip_link.STL" scale="1.00000 1.00000 1.00000"/>
			</geometry>
		</collision>
	</link>
	<joint name="shoulder_pan_joint" type="revolute">
		<parent link="base_link"/>
		<child link="shoulder_link"/>
		<dynamics damping="1.0" friction="0.0001"/>
		<origin rpy="0.00000 -0.00000 0.00000" xyz="0.00000 0.00000 0.12730"/>
		<axis xyz="0.00000 0.00000 1.00000"/>
		<limit effort="330.0" lower="-6.2831853" upper="6.2831853" velocity="2.16"/>
	</joint>
	<joint name="shoulder_lift_joint" type="revolute">
		<parent link="shoulder_link"/>
		<child link="upper_arm_link"/>
		<dynamics damping="1.0" friction="0.0001"/>
		<origin rpy="0.00000 1.57080 -0.00000" xyz="0.00000 0.22094 0.00000"/>
		<axis xyz="0.00000 1.00000 0.00000"/>
		<limit effort="330.0" lower="-6.2831853" upper="6.2831853" velocity="2.16"/>
	</joint>
	<joint name="elbow_joint" type="revolute">
		<parent link="upper_arm_link"/>
		<child link="forearm_link"/>
		<dynamics damping="1.0" friction="0.0001"/>
		<origin rpy="0.00000 -0.00000 0.00000" xyz="0.00000 -0.17190 0.61200"/>
		<axis xyz="0.00000 1.00000 0.00000"/>
		<limit effort="150.0" lower="-6.2831853" upper="6.2831853" velocity="3.15"/>
	</joint>
	<joint name="wrist_1_joint" type="revolute">
		<parent link="forearm_link"/>
		<child link="wrist_1_link"/>
		<dynamics damping="1.0" friction="0.0001"/>
		<origin rpy="0.00000 1.57080 -0.00000" xyz="0.00000 0.00000 0.57230"/>
		<axis xyz="0.00000 1.00000 0.00000"/>
		<limit effort="54.0" lower="-6.2831853" upper="6.2831853" velocity="3.2"/>
	</joint>
	<joint name="wrist_2_joint" type="revolute">
		<parent link="wrist_1_link"/>
		<child link="wrist_2_link"/>
		<dynamics damping="1.0" friction="0.0001"/>
		<origin rpy="0.00000 -0.00000 0.00000" xyz="0.00000 0.11490 0.00000"/>
		<axis xyz="0.00000 0.00000 1.00000"/>
		<limit effort="54.0" lower="-6.2831853" upper="6.2831853" velocity="3.2"/>
	</joint>
	<joint name="wrist_3_joint" type="revolute">
		<parent link="wrist_2_link"/>
		<child link="wrist_3_link"/>
		<dynamics damping="1.0" friction="0.0001"/>
		<origin rpy="0.00000 -0.00000 0.00000" xyz="0.00000 0.00000 0.11570"/>
		<axis xyz="0.00000 1.00000 0.00000"/>
		<limit effort="54.0" lower="-6.2831853" upper="6.2831853" velocity="3.2"/>
	</joint>
	<joint name="ee_fixed_joint" type="fixed">
		<parent link="wrist_3_link"/>
		<child link="ee_link"/>
		<dynamics damping="1.0" friction="0.0001"/>
		<origin rpy="0.00000 -0.00000 1.57080" xyz="0.00000 0.09220 0.00000"/>
		<axis xyz="0.00000 0.00000 0.00000"/>
	</joint>
	<joint name="joint_dummy1" type="fixed">
		<parent link="ee_link"/>
		<child link="base_link2"/>
		<dynamics damping="1.0" friction="0.0001"/>
		<origin rpy="1.57080 0.00000 1.57080" xyz="0.00000 0.00000 0.00000"/>
		<axis xyz="0.00000 0.00000 1.00000"/>
	</joint>
	<joint name="soft_tip_joint" type="fixed">
		<parent link="base_link2"/>
		<child link="soft_tip_link"/>
		<dynamics damping="1.0" friction="0.0001"/>
		<origin rpy="0.00000 -0.00000 -3.14159" xyz="0.11596 0.03850 0.13359"/>
		<axis xyz="0.00000 0.00000 0.00000"/>
	</joint>
	<joint name="rigid_joint" type="revolute">
		<parent link="base_link2"/>
		<child link="rigid_link"/>
		<dynamics damping="1.0" friction="0.0001"/>
		<origin rpy="0.00000 -0.00000 0.00000" xyz="-0.01800 0.03725 0.06000"/>
		<axis xyz="0.00000 1.00000 0.00000"/>
		<limit
		  lower="-3.1415926"
		  upper="3.1415926"
		  effort="0"
		  velocity="0" />
	</joint>
	<joint name="rigid_tip_joint" type="fixed">
		<parent link="rigid_link"/>
		<child link="rigid_tip_link"/>
		<dynamics damping="1.0" friction="0.0001"/>
		<origin rpy="0.00000 -0.00000 3.14159" xyz="-0.06375 0.00000 0.10766"/>
		<axis xyz="0.00000 0.00000 0.00000"/>
	</joint>
</robot>
