<?xml version="1.0" encoding="utf-8"?>
<!-- This URDF was automatically created by SolidWorks to URDF Exporter! Originally created by Stephen Brawner (brawner@gmail.com) 
     Commit Version: 1.5.1-0-g916b5db  Build Version: 1.5.7152.31018
     For more information, please see http://wiki.ros.org/sw_urdf_exporter -->
<robot
  name="soft hybrid gripper urdf">
  <link
    name="base_link">
    <inertial>
      <origin
        xyz="0.000145101013892542 -0.00378632233575341 0.0059852456265876"
        rpy="0 0 0" />
      <mass
        value="0.148725082232704" />
      <inertia
        ixx="0.000369365327864119"
        ixy="1.72344899482905E-05"
        ixz="6.18058496061373E-06"
        iyy="7.90668071224765E-05"
        iyz="-2.47099404881235E-05"
        izz="0.000422474789754775" />
    </inertial>
    <visual>
      <origin
        xyz="0 0 0"
        rpy="0 0 0" />
      <geometry>
        <mesh
          filename="package://hybrid_gripper_cam/meshes/base_link.STL" />
      </geometry>
      <material
        name="">
        <color
          rgba="0.792156862745098 0.819607843137255 0.933333333333333 1" />
      </material>
    </visual>
    <collision>
      <origin
        xyz="0 0 0"
        rpy="0 0 0" />
      <geometry>
        <mesh
          filename="package://hybrid_gripper_cam/meshes/base_link.STL" />
      </geometry>
    </collision>
  </link>
  <link
    name="rigid_link">
    <inertial>
      <origin
        xyz="-0.00964348839257984 0.00389924825406054 0.00922886431149911"
        rpy="0 0 0" />
      <mass
        value="0.0445322517963871" />
      <inertia
        ixx="1.01728770247328E-05"
        ixy="-4.93649549072555E-08"
        ixz="4.49698471699929E-06"
        iyy="1.35940815749742E-05"
        iyz="3.91281583145286E-08"
        izz="1.15340134179683E-05" />
    </inertial>
    <visual>
      <origin
        xyz="0 0 0"
        rpy="0 0 0" />
      <geometry>
        <mesh
          filename="package://hybrid_gripper_cam/meshes/rigid_link.STL" />
      </geometry>
      <material
        name="">
        <color
          rgba="0.250980392156863 0.250980392156863 0.250980392156863 1" />
      </material>
    </visual>
    <collision>
      <origin
        xyz="0 0 0"
        rpy="0 0 0" />
      <geometry>
        <mesh
          filename="package://hybrid_gripper_cam/meshes/rigid_link.STL" />
      </geometry>
    </collision>
  </link>
  <joint
    name="rigid_rev_joint"
    type="revolute">
    <origin
      xyz="-0.018 0.0604 0.031"
      rpy="0 0 0" />
    <parent
      link="base_link" />
    <child
      link="rigid_link" />
    <axis
      xyz="0 -1 0" />
    <limit
      lower="0"
      upper="0"
      effort="0"
      velocity="0" />
  </joint>
  <link
    name="rigid_tip_link">
    <inertial>
      <origin
        xyz="-0.00774095772540721 0.000849999999999657 -0.0611318896625764"
        rpy="0 0 0" />
      <mass
        value="0.0134476259243688" />
      <inertia
        ixx="4.91541805903651E-06"
        ixy="9.70369871279401E-22"
        ixz="-8.62881671033876E-07"
        iyy="4.67899851023963E-06"
        iyz="-1.43787994485692E-21"
        izz="1.28227238645746E-06" />
    </inertial>
    <visual>
      <origin
        xyz="0 0 0"
        rpy="0 0 0" />
      <geometry>
        <mesh
          filename="package://hybrid_gripper_cam/meshes/rigid_tip_link.STL" />
      </geometry>
      <material
        name="">
        <color
          rgba="0.792156862745098 0.819607843137255 0.933333333333333 1" />
      </material>
    </visual>
    <collision>
      <origin
        xyz="0 0 0"
        rpy="0 0 0" />
      <geometry>
        <mesh
          filename="package://hybrid_gripper_cam/meshes/rigid_tip_link.STL" />
      </geometry>
    </collision>
  </link>
  <joint
    name="rigid_tip_joint"
    type="continuous">
    <origin
      xyz="-0.083663 -0.00085 0.089665"
      rpy="0 -0.86027 0" />
    <parent
      link="rigid_link" />
    <child
      link="rigid_tip_link" />
    <axis
      xyz="0 1 0" />
  </joint>
  <link
    name="soft_tip_link">
    <inertial>
      <origin
        xyz="-0.0672819098084754 -5.77278609914522E-08 -0.00123656065002749"
        rpy="0 0 0" />
      <mass
        value="0.0267549348618611" />
      <inertia
        ixx="2.96189216662522E-06"
        ixy="6.27344819191878E-11"
        ixz="-5.21931039474125E-06"
        iyy="3.93840137119762E-05"
        iyz="-4.51104709693914E-12"
        izz="3.84440209403678E-05" />
    </inertial>
    <visual>
      <origin
        xyz="0 0 0"
        rpy="0 0 0" />
      <geometry>
        <mesh
          filename="package://hybrid_gripper_cam/meshes/soft_tip_link.STL" />
      </geometry>
      <material
        name="">
        <color
          rgba="0.792156862745098 0.819607843137255 0.933333333333333 1" />
      </material>
    </visual>
    <collision>
      <origin
        xyz="0 0 0"
        rpy="0 0 0" />
      <geometry>
        <mesh
          filename="package://hybrid_gripper_cam/meshes/soft_tip_link.STL" />
      </geometry>
    </collision>
  </link>
  <joint
    name="soft_tip_joint"
    type="fixed">
    <origin
      xyz="0.11681 0.061 0.098742"
      rpy="0 -0.66549 0" />
    <parent
      link="base_link" />
    <child
      link="soft_tip_link" />
    <axis
      xyz="0 0 0" />
  </joint>
</robot>
